Workbook
Name AfA_Art: Parameter!$B$19
Name AfA_Tabelle: AfA!$A$16:$F$46
Name AFABasis: Parameter!$B$20
Name Annuität_Förderkredit: Parameter!$I$66
Name Annuität_Kredit_1_p.a.: Parameter!$B$66
Name Annuität_Kredit_2_p.a.: Parameter!$B$75
Name Anschlusskredit: Parameter!$B$70
Name Anzahl_Tilgungszuschüsse: Parameter!$I$62
Name AuszahungKredit1: Parameter!$B$63
Name Baukostensteigerung_p.a: Parameter!$B$25
Name BeginnFolgeKredit: Parameter!$D$69
Name Deg5Lin2: AfA!$C$15
Name Deg5Lin3: AfA!$B$15
Name Disagio: Parameter!$B$62
Name Disagio_in_Prozent: Parameter!$B$61
Name Eigenkapital: Parameter!$B$51
Name Finanzbedarf: Parameter!$B$53
Name FinZeitraum: Parameter!$B$54
Name FittingUp: Parameter!$B$14
Name Förderkredit: Parameter!$I$59
Name Förderzeit: Parameter!$I$57
Name Förderzins: Parameter!$I$64
Name Gebäude: Parameter!$B$6
Name Grenzsteuersatz: Parameter!$B$47
Name Grundbuchamt: Parameter!$B$10
Name Grunderwerbsteuer: Parameter!$B$8
Name Grundstück: Parameter!$B$5
Name Instanhaltungskosten_am_Anfang: Parameter!$B$15
Name Investment: Parameter!$B$52
Name Kreditbedarf: Parameter!$B$59
Name Kreditzins1: Parameter!$B$64
Name Kreditzins2: Parameter!$B$71
Name LaufzeitKredit1: Parameter!$B$57
Name LaufzeitKredit2: Parameter!$D$69
Name Lebensdauer: Parameter!$B$18
Name Linear2: AfA!$E$15
Name Linear3: AfA!$D$15
Name LinearX: AfA!$F$15
Name Maklergebühren: Parameter!$B$9
Name Mietpreissteigerung_p.a.: Parameter!$B$44
Name Notargebühren: Parameter!$B$11
Name RBWnach6Jahren: 'Cash & Assets'!$AD$13
Name Restlaufzeit: Parameter!$B$73
Name Start: Parameter!$E$3
Name Startjahr: Parameter!$B$3
Name Tilgungszuschuss: Parameter!$I$61
Name Unterhaltskosten_p.a.: Parameter!$B$33
Name Unterhaltskostensteigerung: Parameter!$B$34
Name Verkaufsjahr: Parameter!#REF!
Name Wertverlust_des_Gebäudes_p.a.: Parameter!$B$23
Name Wertzuwachst_des_Grundstücks_p.a.: Parameter!$B$24

Sheet Hinweise
A1: Was bringt eine vermietete Immobilie? | F1: Version | G1: V 5.1 | H1: vom | I1: 46002
A2: Wie muss ein Immobilien-Investor rechnen?
A3: Modellrechnung
A4: Nach-Steuer-Belastung einer vermieteten, kredit-finanzierten Immobilie!
A6: Die Dateneingabe der Paramater erfolgt durch
A7: Übertippen der Eingaben in den gelben Feldern
A8: in dem Arbeitsblatt "Parameter"
A10: Warnung:
A12: Diese Excel-Kalkulation wird kostenfrei ohne Haftungs- und Gewährleistungsansprüche überlassen.
A13: Dieses Tool ersetzt keine fundierte Rechts-, Steuer- oder Finanzberatung.
A14: Dieses Tool stellt ein Nebenprodukt meiner Tätigkeit in meinen Private Office dar und wurde nicht entwickelt, um es als Produkt zu vermarkten.
A15: Es wird keine Gewährleistung und Haftung für die Richtigkeit der Kalkulationen übernommen.
A16: Es handelt sich um eine Modellrechnung (Szenario-Rechnung) und keine Prognose. Das bedeutet, da Ergebnis zeigt lediglich,
... A75: Die degressive AfA (Absetzung für Abnutzung) im Überblick
A76: Quelle: | B76: https://www.bmwsb.bund.de/SharedDocs/kurzmeldungen/Webs/BMWSB/DE/2024/03/degressive-afa.html
A77: Die degressive Abschreibung gilt ausschließlich für neu gebaute bzw. im Jahr der Fertigstellung erworbene Wohngebäude und Wohnungen.
A78: Im ersten Jahr können fünf Prozent der Investitionskosten steuerlich geltend gemacht werden. In den folgenden Jahren können jeweils fünf Prozent des Restwertes steuerlich geltend gemacht werden.
A79: Ein Wechsel zur linearen AfA ist möglich.
A80: Der Baubeginn des Wohngebäudes muss zwischen dem 1. Oktober 2023 und dem 30. September 2029 (6-Jahres Zeitraum) liegen.
A81: * Höhe der degressiven AfA: 5 % pro Jahr
A82: * Dauer der degressiven Abschreibung: 6 Jahre
A83: * Wechsel zur linearen AfA lohnt sich ab dem 7. Jahr oder wenn die lineare AfA (3 %) höher ist als die degressive AfA
A84: Erstmals ist nicht der Bauantrag entscheidendes Kriterium für die Gewährung der degressiven AfA, sondern der angezeigte Baubeginn. So wollen wir auch die Umsetzung von Projekten anreizen, die zwar schon geplant, aber aus unterschiedlichen Gründen – z. B. Probleme bei der Finanzierung – noch nicht begonnen wurden. Damit soll auch der Bauüberhang von mehr als 800.000 genehmigten Wohnungen abgebaut werden.
A85: Beim Erwerb einer Immobilie muss der Vertrag zwischen dem 1. Oktober 2023 und dem 30. September 2029 rechtswirksam geschlossen werden. Die Immobilie muss bis zum Ende des Jahres der Fertigstellung erworben werden.
A86: Die degressive AfA kann zudem mit der Sonderabschreibung für den Mietwohnungsneubau kombiniert werden. Begünstigt werden dabei Neubauten, mit dem energetischen Gebäudestandard EH40/QNG, die eine Baukostenobergrenze von 5.200 Euro pro m² einhalten.
A87: Die Bedingungen für die genannte Sonderabschreibung für den Mietwohnungsneubau wurden mit dem Wachstumschancengesetz nochmal verbessert: Der Anwendungszeitraum für Neufälle wurde bis Ende September 2029 verlängert, die Baukostenobergrenze von 4.800 Euro pro m² auf 5.200 Euro pro m² und die begünstigten Herstellungs-/Anschaffungskosten von 2.500 Euro pro m² auf 4.000 Euro pro m² erhöht.
A88: siehe auch: | B88: https://ivd.net/bundesverband/steuerliche-vorteile-im-wohnungsbau-degressive-afa-sonderabschreibung
A90: Beispielrechnung
A91: Bei 400.000 Euro Investitionskosten kann der Investor im ersten Jahr 20.000 Euro (5 Prozent von 400.000 Euro) steuerlich abschreiben, im zweiten Jahr sind dann 19.000 Euro abschrei-bungsfähig (400.000 Euro abzüglich der 20.000 Euro vom ersten Jahr = 380.000 Euro Restwert). Innerhalb von sechs Jahren nach Fertigstellung/Erwerb der Immobilie kann der Investor so rund 106.000 Euro steuerlich geltend machen (d.h. auf diesen Betrag müssen keine Steuern entrichtet werden).
A94: Lineare AfA: Drei statt zwei Prozent ab dem 1.1.2023
A95: Quelle: | B95: https://www.haufe.de/immobilien/wirtschaft-politik/abschreibung-beim-mietwohnungsbau_84342_572146.html
A96: § 7 Abs. 4 Satz 1 Nr. 2 EStG: Die lineare Absetzung für Abnutzung (lineare AfA) wurde zum 1.1.2023 von zwei auf drei Prozent pro Jahr angehoben. Darauf hatten sich die Ampel-Parteien bereits im Koalitionsvertrag verständigt.
A97: Die aus dem Ansatz des höheren pauschalen AfA-Satzes resultierende kürzere Abschreibungsdauer von 33 Jahren hat aber keinen Einfluss auf die Beurteilung der tatsächlichen Nutzungsdauer von Wohngebäuden. Diese wird regelmäßig auch mehr als 50 Jahre betragen.
A98: Die Maßnahme gilt für ab dem 1.1.2023 fertiggestellte Wohngebäude (Regierungsentwurf: 30.6.2023).
A100: siehe auch: | B100: https://prozentguru.de/gebaeude-afa-3-prozent/
A101: siehe auch: | B101: https://www.baumeister-online.de/nachricht/bundesrat-stimmt-wachstumschancengesetz-zu-degressive-afa-kommt/
A107: Die jährliche (Anfangs-)Tilgung
A109: Die jährliche (Anfangs-)Tilgung kann in diesem Modell nicht explizit als Parameter eingeben werden.
A110: Die Höhe der Tilgung p.a. in Prozent hängt ab von der gewählten Finanzierungsdauer (Finanzierungszeitraum, siehe Blatt „Parameter“ Zelle B54).
A111: Die Tilgung in % p.a. findet sich in der Spalte K des Blatts „Cash & Assets“
...

Sheet Parameter
A1: Dateneingabe: | B1: in den Gelben Parameter-Feldern | F1: Objekt und Größe | M1: Grunderwerbsteuer nach Bundesländern
A2: Parameter für vermietes Objekt | B2: Version vom | C2: =Hinweise!I1 -> 46002 | F2: Adresse | G2: Ladengeschäft, Musterstraße 123, 45678 Irgendwo | M2: Baden-Württemberg | N2: 0.05
A3: Kauf am: | B3: 46023 | C3: = Start bzw.Jahr | E3: 0 | F3: Nutz- u.Wohnfläche | G3: =B7 -> 144 | H3: Grundstück | I3: 500 | M3: Bayern | N3: 0.035
A4: Kaufpreis (Grundstück & Gebäude) | B4: =Grundstück+Gebäude -> 1000000 | C4: =IF(C5+C6<>1," Check Anteile!","") | M4: Berlin | N4: 0.06
A5: davon für Grundstück | B5: 200000 | C5: =Grundstück/B4 -> 0.2 | D5: Grundstücksanteil am Kaufpreis | H5: =Grundstück/I3 -> 400 | I5: pro m² Gund | J5: vgl. Bodenrichtwert | M5: Brandenburg | N5: 0.065
A6: davon für Gebäude | B6: 800000 | C6: =Gebäude/B4 -> 0.8 | D6: Gebäudeanteil am Kaufpreis; dient zum Verrechnen der anteiligen Erwerbsnebenkosten | M6: Bremen | N6: 0.05
A7: Anzahl Quadratmeter Nutz- u. Wohnfläche | B7: 144 | C7: =B4/B7 -> 6944.4444 | D7: Preis für Nutz- u. Wohnraum pro m² (mit Grundst. gerechnet) | M7: Hamburg | N7: 0.045
A8: Grunderwerbsteuer | B8: =(Gebäude+Grundstück)*C8 -> 50000 | C8: 0.05 | D8: auf Kaufpreis (=Grund & Gebäude) | M8: Hessen | N8: 0.06
A9: Maklergebühren | B9: =(Gebäude+Grundstück)*C9 -> 35700 | C9: =1.19*3% -> 0.0357 | D9: auf Kaufpreis (unterschiedlich je Bundesland) | M9: Mecklenburg-Vorpommern | N9: 0.05
A10: Grundbuch Amt | B10: =(Gebäude+Grundstück)*C10 -> 5000 | C10: 0.005 | D10: geschätzt, kann variieren | M10: Niedersachsen | N10: 0.05
A11: Notargebühren | B11: =(Gebäude+Grundstück)*C11 -> 15000 | C11: 0.015 | D11: geschätzt, muss beim Notar erfragt werden! | M11: Nordrhein-Westfalen | N11: 0.065
A12: Gründung Immobilien Gesellschaft | B12: 0 | M12: Rheinland-Pfalz | N12: 0.05
A13: Erwerbsnebenkosten (ENK) | B13: =SUM(B8:B12) -> 105700 | C13: =SUM(C8:C11) -> 0.1057 | M13: Saarland | N13: 0.065
A14: Fitting up (erhöht den Gebäudewert) | B14: 40000 | C14: Das Fitting up erhöht den Gebäudewert und wird über die Abschreibungsdauer abgeschrieben. | M14: Sachsen | N14: 0.035
A15: Instandsetzung am Anfang | B15: 2500 | C15: Die Instandsetzungskosten (z.B. Reparaturen) werden im Jahr des Kaufs steuerlich angesetzt! | M15: Sachsen-Anhalt | N15: 0.05
A16: Gesamtkosten | B16: =Instanhaltungskosten_am_Anfang+FittingUp+B4+B13 -> 1148200 | C16: Investitionsvolumen (ohne Disagio) | M16: Schleswig-Holstein | N16: 0.065
M17: Thüringen | N17: 0.065
A18: Gebäude-Abschreibung über | B18: 50 | C18: Jahre | D18: der Restnutzungsdauer
A19: AfA: Linear oder Degressiv-Linear? | B19: Linear 2% | C19: <- Klicke auf Zelle & Wähle mit Lasche!
A20: AfA Basis (Gebäudewert + anteilige ENK) | B20: =Gebäude+FittingUp+B13*C6 -> 924560 | C20: = Gebäudewert bei Kauf + Fittiing up + anteilige Erwerbsnebenkosten (ENK)
A22: Asset-Wertentwicklung
A23: Wertverlust des Gebäudes p.a. | B23: 0.01 | C23: Altersabschlag = Parameter für Verkaufswertermittlung
A24: Wertzuwachs des Grundstücks p.a. | B24: 0.01 | C24: Parameter für Verkaufswertermittlung | L24: Maklerprovision | M24: in % | N24: Stand 2020
A25: Preissteigerung von Baukosten p.a. | B25: 0.015 | C25: Parameter für Verkaufswertermittlung | L25: Deutschland | M25: 0.04375 | N25: Durchschn.
A27: Sondertilgungen und Sonderabschreibungen sind in der Tabelle "Cash & Assets" manuell einzugeben! | L27: Baden-Wuerttemberg | M27: 0.0357
L28: Bayern | M28: 0.0357
A29: An Mieter umlegbare / weiterbelastare Kosten! n/a | C29: Bleiben außen vor, da diese Kosten nicht selbst sondern vom Mieter getragen werden! | L29: Brandenburg | M29: 0.0714 | O29: Keine Gewähr für die Richtigkeit der Angaben. Dieses Tool ersetzt keine fundierte Rechts-, Steuer- oder Finanzberatung.
A30: Hausverwaltung, Hausmeister, etc. p.a. | B30: 480 | C30: Nicht an Mieter weiterbelastare Kosten! | L30: Hessen | M30: 0.0595
A31: lfd. Reparturen und Instandhaltung p.a. | B31: =B7*C31 -> 864 | C31: 6 | D31: / m² p.a. geschätzt ! Bitte anpassen! | L31: Mecklenburg-Vorpommern | M31: 0.0357
A32: Instandhaltungsrücklage p.a | B32: =B7*C32 -> 720 | C32: 5 | D32: / m² p.a. geschätzt ! Bitte anpassen! | L32: Niedersachsen | M32: 0.05 | N32: 3,57 bis 5,95
A33: Bewirtschtungs-/Unterhaltskosten incl. Instandhaltungsrücklage p.a. | B33: =SUM(B30:B32) -> 2064 | C33: =Unterhaltskosten_p.a./B7 -> 14.333333 | D33: / m² p.a. | L33: Nordrhein-Westfalen | M33: 0.0357
A34: Unterhaltskostensteigerung p.a. | B34: 0.0125 | C34: geschätzt bitte anpassen! | L34: Rheinland-Pfalz | M34: 0.0357
L35: Saarland | M35: 0.0357 | P35: Achtung:
L36: Sachsen-Anhalt | M36: 0.0357 | P36: Änderung der Maklerprovisionen in 2021 erwartet!
A37: Miete p.m. | B37: 4000 | C37: =B37/B7 -> 27.777778 | D37: Mietpreis für Nutzfläche pro m² | L37: Sachsen | M37: 0.0357
A38: Miete p.a. | B38: =B37*12 -> 48000 | C38: =B38/B16 -> 0.041804564 | D38: Brutto-Mietrendite p.a. bezogen auf Investment [ > 5% für Geschäftsmiete anstreben] | L38: Schleswig-Holstein | M38: 0.0357
A39: Durchschn. Mietausfalls-/Leerstandsrisiko | B39: 0.02 | C39: p.a. | D39: wird als Mietminderung in Kalkulation berücksichtigt! | L39: Thüringen | M39: 0.0357
A40: nachhaltige durchschn. Miete p.a. | B40: =B38*(1-B39) -> 47040 | C40: unter Berücksichtigung des Mietausfallsrisikos und der Instandhaltung | L40: Berlin | M40: 0.0714
A41: nachh. Mietrendite p.a. | B41: =B40/B16 -> 0.040968472 | C41: Miete p.a. in Prozent des Investitionsvolumens | L41: Bremen | M41: 0.0595
A42: Investition als Vielfaches der Jahresmiete | B42: =B16/B40 -> 24.409014 | C42: =" Investitionsvolumen entspricht dem "&ROUND(B42,1)&" fachen einer nachh. Jahresmiete" -> Investitionsvolumen entspricht dem 24,4 fachen einer nachh. Jahresmiete | L42: Hamburg | M42: 0.0312
...

Sheet AfA
A1: AfA Varianten
I2: Wähle die Art der AfA in der Tabelle "Parameter" durch Klicken auf die Lasche aus der Dropdown-Liste aus! (siehe Abb.)
B3: AfA Varianten für Wohnimmobilen
B4: Degressiv 5% + Linear 3% | D4: 6 Jahre lang 5 %, danach 3% p,a,
B5: Degressiv 5% + Linear 2% | D5: 6 Jahre lang 5 %, danach 2% p.a.
B6: Linear 3 % p.a. | D6: 33,3 Jahre lang 3% p.a.
B7: Linear 2 % p.a. | D7: 50 Jahre lang 2 % p.a.
B8: AfA Spezial | C8: / Linear x% | D8: abhängig von der Restnutzungsdauer
B9: bei Gewerbeimmobilien bleibt es bei Linear 2 % p.a.
B12: AfA Varianten auf Gebäude über den Zeitverlauf
A15: Jahr | B15: Degressiv 5% u. Linear 3% | C15: Degressiv 5% u. Linear 2% | D15: Linear 3% | E15: Linear 2% | F15: Linear x% | J15: Siehe Information zu AfA unten im Blatt ab Zeile: 63
A16: 1 | B16: 0.05 | C16: 0.05 | D16: 0.03 | E16: 0.02 | F16: =1/Lebensdauer*(A16<=Lebensdauer) -> 0.02 | J16: Die degressive AfA (Absetzung für Abnutzung) im Überblick
A17: 2 | B17: 0.05 | C17: 0.05 | D17: 0.03 | E17: 0.02 | F17: =1/Lebensdauer*(A17<=Lebensdauer) -> 0.02
A18: 3 | B18: 0.05 | C18: 0.05 | D18: 0.03 | E18: 0.02 | F18: =1/Lebensdauer*(A18<=Lebensdauer) -> 0.02
A19: 4 | B19: 0.05 | C19: 0.05 | D19: 0.03 | E19: 0.02 | F19: =1/Lebensdauer*(A19<=Lebensdauer) -> 0.02
A20: 5 | B20: 0.05 | C20: 0.05 | D20: 0.03 | E20: 0.02 | F20: =1/Lebensdauer*(A20<=Lebensdauer) -> 0.02
A21: 6 | B21: 0.05 | C21: 0.05 | D21: 0.03 | E21: 0.02 | F21: =1/Lebensdauer*(A21<=Lebensdauer) -> 0.02
A22: 7 | B22: 0.03 | C22: 0.02 | D22: 0.03 | E22: 0.02 | F22: =1/Lebensdauer*(A22<=Lebensdauer) -> 0.02
A23: 8 | B23: 0.03 | C23: 0.02 | D23: 0.03 | E23: 0.02 | F23: =1/Lebensdauer*(A23<=Lebensdauer) -> 0.02
A24: 9 | B24: 0.03 | C24: 0.02 | D24: 0.03 | E24: 0.02 | F24: =1/Lebensdauer*(A24<=Lebensdauer) -> 0.02
A25: 10 | B25: 0.03 | C25: 0.02 | D25: 0.03 | E25: 0.02 | F25: =1/Lebensdauer*(A25<=Lebensdauer) -> 0.02
A26: 11 | B26: 0.03 | C26: 0.02 | D26: 0.03 | E26: 0.02 | F26: =1/Lebensdauer*(A26<=Lebensdauer) -> 0.02
A27: 12 | B27: 0.03 | C27: 0.02 | D27: 0.03 | E27: 0.02 | F27: =1/Lebensdauer*(A27<=Lebensdauer) -> 0.02
A28: 13 | B28: 0.03 | C28: 0.02 | D28: 0.03 | E28: 0.02 | F28: =1/Lebensdauer*(A28<=Lebensdauer) -> 0.02
... A46: 31 | B46: 0.03 | C46: 0.02 | D46: 0.03 | E46: 0.02 | F46: =1/Lebensdauer*(A46<=Lebensdauer) -> 0.02
F47: ↑
F48: Dieser
F49: Bereich kann
F50: überschrieben
F51: werden mit
F52: den relevanten
F53: AfA % Sätzen
F55: Der angezeigte
F56: %-Satz reflektiert
F57: die AfA über die
F58: Restnutzungsdauer
F59: falls diese <50 Jahre
F60: siehe Parameter B18
A63: Die degressive AfA (Absetzung für Abnutzung) im Überblick
A64: Quelle: | B64: https://www.bmwsb.bund.de/SharedDocs/kurzmeldungen/Webs/BMWSB/DE/2024/03/degressive-afa.html
...

Sheet Cash & Assets
A1: Gewinn- und Verlust-Rechung sowie Cash-Flow-Betrachtung für eine vermietete Immobilie | J1: Asset-Werte: Immobilie, Darlehen, möglicher Überschuss aus Verkauf im Zeitverlauf | S1: Hausbank-Kredit | U1: Hausbank-Kredit | X1: Gewinn- u. Verlust aus Vermietung | AH1: CASH FLOW Entwicklung | AM1: Vermögenszuwachs | AQ1: A S S E T Entwicklung | AW1: R E N D I T E Betrachtung
S2: plus Förderkredit | U2: plus Förderkredit | X2: Beachte: | Z2: (-) = Mittelabfluß / Aufwand | AC2: (+) = Mittelzufluß / Einnahme | AI2: Mittel- | AJ2: Mittel- | AK2: kumul. | AM2: kumulierter | AN2: Vermögens- | AO2: Tilgung und | AS2: Geschätzter | AT2: Geschätzter | AU2: Überschuss | AW2: Überschuss in % | AX2: durchschn. jährliche | AY2: Überschuss in % | AZ2: durchschn. jährliche
D3: Hausbank-Kredit | L3: Förderkredit | S3: Tilgungen | T3: Tilgungen | U3: kumul. | V3: Rest- | X3: Unterhalts- | Y3: nachhaltiger | Z3: =AfA_Art -> Linear 2% | AB3: Sonder-AFA | AC3: AfA p.a. | AD3: Buchwert | AE3: Zu ver- | AI3: zufluss (+) bzw. | AJ3: zufluss (+) bzw. | AK3: Mittel- | AM3: Cash Flow | AN3: zuwachs aus | AO3: kumul. Cash Flow | AQ3: geschätzter | AR3: geschätzter | AS3: Verkehrswert | AT3: Verkehrswert | AU3: aus Verkauf des | AW3: bezogen auf | AX3: Rendite n. Steuer | AY3: im Verhältnis | AZ3: EK Rendite n. Steuer
D4: Restschuld | E4: Zins | F4: Annuität= | G4: Zinsen | H4: Sonder- | I4: Tilgung | J4: Kumul. | K4: Tilgung in % | L4: Restschuld | M4: Zins | N4: Annuität p.a. | O4: Zinsen | P4: Tilgungs- | Q4: Tilgung | R4: Kumul. | S4: p.a. | T4: p.a. | U4: Tilgungen | V4: schulden | X4: kosten u. | Y4: Ertrag aus | Z4: Gebäude | AA4: AfA auf | AB4: auf | AC4: insgesamt | AD4: des Gebäudes | AE4: steuernder | AF4: (Grenz-) | AH4: Steuerzahlung | AI4: Abfluss (-) | AJ4: Abfluss (-) | AK4: zu-/abfluss | AM4: angelegt u. verzinst | AN4: Tilgung und kumul. | AO4: verzinst | AQ4: Marktwert | AR4: Marktwert | AS4: (Verkaufswert) | AT4: minus | AU4: Objektes plus | AW4: Inventment von | AX4: in % v. Investmt. | AY4: zum Eigenkapital | AZ4: in % durch
C5: Eigen- | D5: Bank- | E5: in % | F5: Zins + | G5: p.a. | H5: Tilgung | I5: Hausbank- | J5: Tilgung | K5: Anfangs- | L5: Förder- | M5: Förder- | N5: Förder- | O5: Förder- | P5: zuschuss | Q5: insg. p.a. | R5: Tilgung | S5: insgesamt | T5: insgesamt | U5: insgesamt | V5: insgesamt | X5: Rücklagen u. | Y5: Vermietung | Z5: AFA | AA5: Gebäude | AB5: Gebäude | AC5: auf | AD5: am Ende des | AE5: Gewinn(+) | AF5: Steuer- | AH5: (+) = Ersparnis | AI5: vor Steuer | AJ5: nach Steuern | AK5: nach Steuern | AM5: mit Rendite von | AN5: unverzinsten | AO5: mit Rendite von | AQ5: Grundstück | AR5: Gebäude | AS5: des Objektes | AT5: Darlehns- | AU5: kumul. Tilgung | AW5: =Investment -> 1148200 | AX5: aus Überschuss | AY5: (EK) bei einem | AZ5: Überschuss bei
A6: No. | B6: Jahr | C6: kapital (EK) | D6: kredit | E6: p.a. | F6: Tilgung | G6: in € | H6: p.a. in € | I6: kredit | J6: in € | K6: kredit | L6: kredit | M6: kredit | N6: kredit | O6: kredit | P6: Förd.kredit | Q6: in € | R6: in € | S6: in € | T6: in % | U6: in € | V6: in € | X6: Instandhaltung | Y6: in € p.a. | Z6: in % | AA6: in Euro | AB6: in € | AC6: Gebäude | AD6: Jahres | AE6: Verlust(-) | AF6: satz | AH6: (-) = Zahlung | AI6: p.a. | AJ6: p.a. | AK6: p.a. | AM6: =Parameter!B81 -> 0.04176 | AN6: Cash Flow | AO6: =AM6 -> 0.04176 | AQ6: in € | AR6: in € | AS6: über die Jahre | AT6: Restschuld | AU6: über die Jahre | AW6: bei einem Verkauf | AX6: bei einem Verkauf | AY6: Verkauf | AZ6: einem Verkauf | BA6: Jahr
A7: =Start -> 0 | B7: Start | C7: =Eigenkapital -> 100000 | D7: =AuszahungKredit1 -> 998200 | E7: =-Kreditzins1 -> -0.0285 | F7: p.a. | H7: manuell eingeben | I7: p.a. in € | L7: =Förderkredit -> 50000 | M7: p.a. | N7: p.a. | O7: p.a. | P7: evtl. manuell eingeben | Q7: incl. Förder- zuschuss | AB7: manuell eingeben | AD7: =AFABasis -> 924560 | AE7: aus Vermietung | AI7: =Kreditbedarf+Förderkredit+Eigenkapital-Investment -> 0 | AM7: nach Steuern | AN7: nach Steuern | AO7: nach Steuern | AQ7: =Grundstück -> 200000 | AR7: =Gebäude+FittingUp -> 840000 | AS7: =AQ7+AR7 -> 1040000 | BA7: =B7 -> Start
A8: 1 | B8: =YEAR(Parameter!B3) -> 2026 | D8: =D7 -> 998200 | E8: =IF(A8<=LaufzeitKredit1,-Kreditzins1,IF(A8<=FinZeitraum,-Kreditzins2,0)) -> -0.0285 | F8: =IF(A8<=LaufzeitKredit1,-Annuität_Kredit_1_p.a.,IF(A8<=FinZeitraum,-Annuität_Kredit_2_p.a.,0)) -> -56370.637 | G8: =D8*E8 -> -28448.7 | H8: 0 | I8: =-F8+G8+H8 -> 27921.937 | J8: =J7+I8 -> 27921.937 | K8: =IF(D8>0,-I8/D$8,0) -> -0.027972287 | L8: =Förderkredit -> 50000 | M8: =IF(A8<=Förderzeit,-Förderzins,0) -> -0.0285 | N8: =IF(ISNUMBER(Annuität_Förderkredit),-Annuität_Förderkredit,0)*(A8<=Förderzeit) -> -7077.8193 | O8: =IF(L8>0,L8*M8,0) -> -1425 | P8: =IF(A8<=Anzahl_Tilgungszuschüsse,Tilgungszuschuss,0) -> 1500 | Q8: =-N8+O8+P8 -> 7152.8193 | R8: =Q8 -> 7152.8193 | S8: =Q8+I8 -> 35074.756 | T8: =S8/(AuszahungKredit1+Förderkredit) -> 0.033461893 | U8: =S8+U7 -> 35074.756 | V8: =D8+L8 -> 1048200 | X8: =-Unterhaltskosten_p.a.-Instanhaltungskosten_am_Anfang -> -4564 | Y8: =Parameter!B40 -> 47040 | Z8: =IF(AfA_Art=AfA!B$15,VLOOKUP(A8,AfA_Tabelle,2),IF(AfA_Art=AfA!C$15,VLOOKUP(A8,AfA_Tabelle,3),IF(AfA_Art=AfA!D$15,VLOOKUP(A8,AfA_Tabelle,4),IF(AfA_Art=AfA!E$15,VLOOKUP(A8,AfA_Tabelle,5),IF(AfA_Art=AfA!F$15,VLOOKUP(A8,AfA_Tabelle,6),"tbd"))))) -> 0.02 | AA8: =IF(OR(AfA_Art=AfA!B$15,AfA_Art=AfA!C$15),-Z8*AD7,IF(OR(AfA_Art=AfA!D$15,AfA_Art=AfA!E$15,AfA_Art=AfA!F$15),AFABasis*-Z8,"check")) -> -18491.2 | AB8: 0 | AC8: =AA8+AB8 -> -18491.2 | AD8: =IF(AD7+AC8>=0,AD7+AC8,0) -> 906068.8 | AE8: =Y8+X8+G8+O9+AC8-Disagio -> -5685.0447 | AF8: =-Grenzsteuersatz -> -0.42 | AH8: =AE8*AF8 -> 2387.7188 | AI8: =Y8+X8+F8+H8+N8+P8 -> -19472.456 | AJ8: =AI8+AH8 -> -17084.737 | AK8: =+AJ8+AK7 -> -17084.737 | AM8: =AJ8+(AJ8/2)*AM6 -> -17441.467 | AN8: =+U8+AK8 -> 17990.019 | AO8: =+AM8+U8 -> 17633.289 | AQ8: =AQ7*(1+Wertzuwachst_des_Grundstücks_p.a.) -> 202000 | AR8: =AR7*(1-Wertverlust_des_Gebäudes_p.a.+Baukostensteigerung_p.a) -> 844200 | AS8: =AR8+AQ8 -> 1046200 | AT8: =(AS8-V8)*(V8>0) -> -2000 | AU8: =AS8+AN8-Investment -> -84009.981 | AW8: =AU8/Investment -> -0.073166679 | AX8: =(1+AW8)^(1/A8)-1 -> -0.073166679 | AY8: =IF(Eigenkapital>0,AU8/Eigenkapital,"n/a") -> -0.84009981 | AZ8: =IF(Eigenkapital>0,(1+AY8)^(1/A8)-1,"n/a") -> -0.84009981 | BA8: =B8 -> 2026
A9: 2 | B9: =B8+1 -> 2027 | D9: =(A9<=FinZeitraum)*(D8-I8) -> 970278.06 | E9: =IF(A9<=LaufzeitKredit1,-Kreditzins1,IF(A9<=FinZeitraum,-Kreditzins2,0)) -> -0.0285 | F9: =IF(A9<=LaufzeitKredit1,-Annuität_Kredit_1_p.a.,IF(A9<=FinZeitraum,-Annuität_Kredit_2_p.a.,0)) -> -56370.637 | G9: =D9*E9 -> -27652.925 | H9: 0 | I9: =-F9+G9+H9 -> 28717.712 | J9: =J8+I9 -> 56639.649 | K9: =IF(D9>0,-I9/D$8,0) -> -0.028769497 | L9: =IF(L8-Q8<0,0,L8-Q8) -> 42847.181 | M9: =IF(A9<=Förderzeit,-Förderzins,0) -> -0.0285 | N9: =IF(ISNUMBER(Annuität_Förderkredit),-Annuität_Förderkredit,0)*(A9<=Förderzeit) -> -7077.8193 | O9: =IF(L9>0,L9*M9,0) -> -1221.1447 | P9: =IF(A9<=Anzahl_Tilgungszuschüsse,Tilgungszuschuss,0) -> 1500 | Q9: =-N9+O9+P9 -> 7356.6746 | R9: =R8+Q9 -> 14509.494 | S9: =Q9+I9 -> 36074.387 | T9: =S9/(AuszahungKredit1+Förderkredit) -> 0.034415557 | U9: =S9+U8 -> 71149.143 | V9: =D9+L9 -> 1013125.2 | X9: =-Unterhaltskosten_p.a.*(1+Unterhaltskostensteigerung)^2 -> -2115.9225 | Y9: =Y8*(1+Mietpreissteigerung_p.a.) -> 47628 | Z9: =IF(AfA_Art=AfA!B$15,VLOOKUP(A9,AfA_Tabelle,2),IF(AfA_Art=AfA!C$15,VLOOKUP(A9,AfA_Tabelle,3),IF(AfA_Art=AfA!D$15,VLOOKUP(A9,AfA_Tabelle,4),IF(AfA_Art=AfA!E$15,VLOOKUP(A9,AfA_Tabelle,5),IF(AfA_Art=AfA!F$15,VLOOKUP(A9,AfA_Tabelle,6),"tbd"))))) -> 0.02 | AA9: =IF(OR(AfA_Art=AfA!B$15,AfA_Art=AfA!C$15),-Z9*AD8,IF(OR(AfA_Art=AfA!D$15,AfA_Art=AfA!E$15,AfA_Art=AfA!F$15),AFABasis*-Z9,"check")) -> -18491.2 | AB9: 0 | AC9: =AA9+AB9 -> -18491.2 | AD9: =IF(AD8+AC9>=0,AD8+AC9,0) -> 887577.6 | AE9: =Y9+X9+G9+O9+AC9 -> -1853.192 | AF9: =-Grenzsteuersatz -> -0.42 | AH9: =AE9*AF9 -> 778.34062 | AI9: =Y9+X9+F9+H9+N9+P9 -> -16436.379 | AJ9: =AI9+AH9 -> -15658.038 | AK9: =+AJ9+AK8 -> -32742.775 | AM9: =AM8*(1+AM$6)+(AJ9/2)*AM$6+AJ9 -> -34154.8 | AN9: =+U9+AK9 -> 38406.367 | AO9: =+AM9+U9 -> 36994.343 | AQ9: =AQ8*(1+Wertzuwachst_des_Grundstücks_p.a.) -> 204020 | AR9: =AR8*(1-Wertverlust_des_Gebäudes_p.a.+Baukostensteigerung_p.a) -> 848421 | AS9: =AR9+AQ9 -> 1052441 | AT9: =(AS9-V9)*(V9>0) -> 39315.756 | AU9: =AS9+AN9-Investment -> -57352.633 | AW9: =AU9/Investment -> -0.049950037 | AX9: =(1+AW9)^(1/A9)-1 -> -0.025294935 | AY9: =IF(Eigenkapital>0,AU9/Eigenkapital,"n/a") -> -0.57352633 | AZ9: =IF(Eigenkapital>0,(1+AY9)^(1/A9)-1,"n/a") -> -0.34695048 | BA9: =B9 -> 2027
A10: 3 | B10: =B9+1 -> 2028 | D10: =(A10<=FinZeitraum)*(D9-I9) -> 941560.35 | E10: =IF(A10<=LaufzeitKredit1,-Kreditzins1,IF(A10<=FinZeitraum,-Kreditzins2,0)) -> -0.0285 | F10: =IF(A10<=LaufzeitKredit1,-Annuität_Kredit_1_p.a.,IF(A10<=FinZeitraum,-Annuität_Kredit_2_p.a.,0)) -> -56370.637 | G10: =D10*E10 -> -26834.47 | H10: 0 | I10: =-F10+G10+H10 -> 29536.167 | J10: =J9+I10 -> 86175.816 | K10: =IF(D10>0,-I10/D$8,0) -> -0.029589428 | L10: =IF(L9-Q9<0,0,L9-Q9) -> 35490.506 | M10: =IF(A10<=Förderzeit,-Förderzins,0) -> -0.0285 | N10: =IF(ISNUMBER(Annuität_Förderkredit),-Annuität_Förderkredit,0)*(A10<=Förderzeit) -> -7077.8193 | O10: =IF(L10>0,L10*M10,0) -> -1011.4794 | P10: =IF(A10<=Anzahl_Tilgungszuschüsse,Tilgungszuschuss,0) -> 1500 | Q10: =-N10+O10+P10 -> 7566.3398 | R10: =R9+Q10 -> 22075.834 | S10: =Q10+I10 -> 37102.507 | T10: =S10/(AuszahungKredit1+Förderkredit) -> 0.0353964 | U10: =S10+U9 -> 108251.65 | V10: =D10+L10 -> 977050.86 | X10: =X9*(1+Unterhaltskostensteigerung) -> -2142.3715 | Y10: =Y9*(1+Mietpreissteigerung_p.a.) -> 48223.35 | Z10: =IF(AfA_Art=AfA!B$15,VLOOKUP(A10,AfA_Tabelle,2),IF(AfA_Art=AfA!C$15,VLOOKUP(A10,AfA_Tabelle,3),IF(AfA_Art=AfA!D$15,VLOOKUP(A10,AfA_Tabelle,4),IF(AfA_Art=AfA!E$15,VLOOKUP(A10,AfA_Tabelle,5),IF(AfA_Art=AfA!F$15,VLOOKUP(A10,AfA_Tabelle,6),"tbd"))))) -> 0.02 | AA10: =IF(OR(AfA_Art=AfA!B$15,AfA_Art=AfA!C$15),-Z10*AD9,IF(OR(AfA_Art=AfA!D$15,AfA_Art=AfA!E$15,AfA_Art=AfA!F$15),AFABasis*-Z10,"check")) -> -18491.2 | AB10: 0 | AC10: =AA10+AB10 -> -18491.2 | AD10: =IF(AD9+AC10>=0,AD9+AC10,0) -> 869086.4 | AE10: =Y10+X10+G10+O10+AC10 -> -256.17096 | AF10: =-Grenzsteuersatz -> -0.42 | AH10: =AE10*AF10 -> 107.5918 | AI10: =Y10+X10+F10+H10+N10+P10 -> -15867.478 | AJ10: =AI10+AH10 -> -15759.886 | AK10: =+AJ10+AK9 -> -48502.661 | AM10: =AM9*(1+AM$6)+(AJ10/2)*AM$6+AJ10 -> -51670.057 | AN10: =+U10+AK10 -> 59748.988 | AO10: =+AM10+U10 -> 56581.593 | AQ10: =AQ9*(1+Wertzuwachst_des_Grundstücks_p.a.) -> 206060.2 | AR10: =AR9*(1-Wertverlust_des_Gebäudes_p.a.+Baukostensteigerung_p.a) -> 852663.1 | AS10: =AR10+AQ10 -> 1058723.3 | AT10: =(AS10-V10)*(V10>0) -> 81672.448 | AU10: =AS10+AN10-Investment -> -29727.707 | AW10: =AU10/Investment -> -0.025890704 | AX10: =(1+AW10)^(1/A10)-1 -> -0.0087058059 | AY10: =IF(Eigenkapital>0,AU10/Eigenkapital,"n/a") -> -0.29727707 | AZ10: =IF(Eigenkapital>0,(1+AY10)^(1/A10)-1,"n/a") -> -0.1109462 | BA10: =B10 -> 2028
A11: 4 | B11: =B10+1 -> 2029 | D11: =(A11<=FinZeitraum)*(D10-I10) -> 912024.18 | E11: =IF(A11<=LaufzeitKredit1,-Kreditzins1,IF(A11<=FinZeitraum,-Kreditzins2,0)) -> -0.0285 | F11: =IF(A11<=LaufzeitKredit1,-Annuität_Kredit_1_p.a.,IF(A11<=FinZeitraum,-Annuität_Kredit_2_p.a.,0)) -> -56370.637 | G11: =D11*E11 -> -25992.689 | H11: 0 | I11: =-F11+G11-H11 -> 30377.948 | J11: =J10+I11 -> 116553.76 | K11: =IF(D11>0,-I11/D$8,0) -> -0.030432727 | L11: =IF(L10-Q10<0,0,L10-Q10) -> 27924.166 | M11: =IF(A11<=Förderzeit,-Förderzins,0) -> -0.0285 | N11: =IF(ISNUMBER(Annuität_Förderkredit),-Annuität_Förderkredit,0)*(A11<=Förderzeit) -> -7077.8193 | O11: =IF(L11>0,L11*M11,0) -> -795.83874 | P11: =IF(A11<=Anzahl_Tilgungszuschüsse,Tilgungszuschuss,0) -> 1500 | Q11: =-N11+O11+P11 -> 7781.9805 | R11: =R10+Q11 -> 29857.814 | S11: =Q11+I11 -> 38159.928 | T11: =S11/(AuszahungKredit1+Förderkredit) -> 0.036405198 | U11: =S11+U10 -> 146411.58 | V11: =D11+L11 -> 939948.35 | X11: =X10*(1+Unterhaltskostensteigerung) -> -2169.1512 | Y11: =Y10*(1+Mietpreissteigerung_p.a.) -> 48826.142 | Z11: =IF(AfA_Art=AfA!B$15,VLOOKUP(A11,AfA_Tabelle,2),IF(AfA_Art=AfA!C$15,VLOOKUP(A11,AfA_Tabelle,3),IF(AfA_Art=AfA!D$15,VLOOKUP(A11,AfA_Tabelle,4),IF(AfA_Art=AfA!E$15,VLOOKUP(A11,AfA_Tabelle,5),IF(AfA_Art=AfA!F$15,VLOOKUP(A11,AfA_Tabelle,6),"tbd"))))) -> 0.02 | AA11: =IF(OR(AfA_Art=AfA!B$15,AfA_Art=AfA!C$15),-Z11*AD10,IF(OR(AfA_Art=AfA!D$15,AfA_Art=AfA!E$15,AfA_Art=AfA!F$15),AFABasis*-Z11,"check")) -> -18491.2 | AB11: 0 | AC11: =AA11+AB11 -> -18491.2 | AD11: =IF(AD10+AC11>=0,AD10+AC11,0) -> 850595.2 | AE11: =Y11+X11+G11+O11+AC11 -> 1377.2627 | AF11: =-Grenzsteuersatz -> -0.42 | AH11: =AE11*AF11 -> -578.45034 | AI11: =Y11+X11+F11+H11+N11+P11 -> -15291.465 | AJ11: =AI11+AH11 -> -15869.916 | AK11: =+AJ11+AK10 -> -64372.577 | AM11: =AM10*(1+AM$6)+(AJ11/2)*AM$6+AJ11 -> -70029.078 | AN11: =+U11+AK11 -> 82039.001 | AO11: =+AM11+U11 -> 76382.5 | AQ11: =AQ10*(1+Wertzuwachst_des_Grundstücks_p.a.) -> 208120.8 | AR11: =AR10*(1-Wertverlust_des_Gebäudes_p.a.+Baukostensteigerung_p.a) -> 856926.42 | AS11: =AR11+AQ11 -> 1065047.2 | AT11: =(AS11-V11)*(V11>0) -> 125098.87 | AU11: =AS11+AN11-Investment -> -1113.7768 | AW11: =AU11/Investment -> -0.00097001989 | AX11: =(1+AW11)^(1/A11)-1 -> -0.00024259324 | AY11: =IF(Eigenkapital>0,AU11/Eigenkapital,"n/a") -> -0.011137768 | AZ11: =IF(Eigenkapital>0,(1+AY11)^(1/A11)-1,"n/a") -> -0.0027961479 | BA11: =B11 -> 2029
A12: 5 | B12: =B11+1 -> 2030 | D12: =(A12<=FinZeitraum)*(D11-I11) -> 881646.24 | E12: =IF(A12<=LaufzeitKredit1,-Kreditzins1,IF(A12<=FinZeitraum,-Kreditzins2,0)) -> -0.0285 | F12: =IF(A12<=LaufzeitKredit1,-Annuität_Kredit_1_p.a.,IF(A12<=FinZeitraum,-Annuität_Kredit_2_p.a.,0)) -> -56370.637 | G12: =D12*E12 -> -25126.918 | H12: 0 | I12: =-F12+G12+H12 -> 31243.719 | J12: =J11+I12 -> 147797.48 | K12: =IF(D12>0,-I12/D$8,0) -> -0.031300059 | L12: =IF(L11-Q11<0,0,L11-Q11) -> 20142.186 | M12: =IF(A12<=Förderzeit,-Förderzins,0) -> -0.0285 | N12: =IF(ISNUMBER(Annuität_Förderkredit),-Annuität_Förderkredit,0)*(A12<=Förderzeit) -> -7077.8193 | O12: =IF(L12>0,L12*M12,0) -> -574.05229 | P12: =IF(A12<=Anzahl_Tilgungszuschüsse,Tilgungszuschuss,0) -> 1500 | Q12: =-N12+O12+P12 -> 8003.767 | R12: =R11+Q12 -> 37861.581 | S12: =Q12+I12 -> 39247.486 | T12: =S12/(AuszahungKredit1+Förderkredit) -> 0.037442746 | U12: =S12+U11 -> 185659.06 | V12: =D12+L12 -> 901788.42 | X12: =X11*(1+Unterhaltskostensteigerung) -> -2196.2656 | Y12: =Y11*(1+Mietpreissteigerung_p.a.) -> 49436.469 | Z12: =IF(AfA_Art=AfA!B$15,VLOOKUP(A12,AfA_Tabelle,2),IF(AfA_Art=AfA!C$15,VLOOKUP(A12,AfA_Tabelle,3),IF(AfA_Art=AfA!D$15,VLOOKUP(A12,AfA_Tabelle,4),IF(AfA_Art=AfA!E$15,VLOOKUP(A12,AfA_Tabelle,5),IF(AfA_Art=AfA!F$15,VLOOKUP(A12,AfA_Tabelle,6),"tbd"))))) -> 0.02 | AA12: =IF(OR(AfA_Art=AfA!B$15,AfA_Art=AfA!C$15),-Z12*AD11,IF(OR(AfA_Art=AfA!D$15,AfA_Art=AfA!E$15,AfA_Art=AfA!F$15),AFABasis*-Z12,"check")) -> -18491.2 | AB12: 0 | AC12: =AA12+AB12 -> -18491.2 | AD12: =IF(AD11+AC12>=0,AD11+AC12,0) -> 832104 | AE12: =Y12+X12+G12+O12+AC12 -> 3048.033 | AF12: =-Grenzsteuersatz -> -0.42 | AH12: =AE12*AF12 -> -1280.1739 | AI12: =Y12+X12+F12+H12+N12+P12 -> -14708.253 | AJ12: =AI12+AH12 -> -15988.427 | AK12: =+AJ12+AK11 -> -80361.004 | AM12: =AM11*(1+AM$6)+(AJ12/2)*AM$6+AJ12 -> -89275.758 | AN12: =+U12+AK12 -> 105298.06 | AO12: =+AM12+U12 -> 96383.306 | AQ12: =AQ11*(1+Wertzuwachst_des_Grundstücks_p.a.) -> 210202.01 | AR12: =AR11*(1-Wertverlust_des_Gebäudes_p.a.+Baukostensteigerung_p.a) -> 861211.05 | AS12: =AR12+AQ12 -> 1071413.1 | AT12: =(AS12-V12)*(V12>0) -> 169624.64 | AU12: =AS12+AN12-Investment -> 28511.122 | AW12: =AU12/Investment -> 0.024831147 | AX12: =(1+AW12)^(1/A12)-1 -> 0.0049176248 | AY12: =IF(Eigenkapital>0,AU12/Eigenkapital,"n/a") -> 0.28511122 | AZ12: =IF(Eigenkapital>0,(1+AY12)^(1/A12)-1,"n/a") -> 0.051448833 | BA12: =B12 -> 2030
A13: 6 | B13: =B12+1 -> 2031 | D13: =(A13<=FinZeitraum)*(D12-I12) -> 850402.52 | E13: =IF(A13<=LaufzeitKredit1,-Kreditzins1,IF(A13<=FinZeitraum,-Kreditzins2,0)) -> -0.0285 | F13: =IF(A13<=LaufzeitKredit1,-Annuität_Kredit_1_p.a.,IF(A13<=FinZeitraum,-Annuität_Kredit_2_p.a.,0)) -> -56370.637 | G13: =D13*E13 -> -24236.472 | H13: 0 | I13: =-F13+G13+H13 -> 32134.165 | J13: =J12+I13 -> 179931.65 | K13: =IF(D13>0,-I13/D$8,0) -> -0.032192111 | L13: =IF(L12-Q12<0,0,L12-Q12) -> 12138.419 | M13: =IF(A13<=Förderzeit,-Förderzins,0) -> -0.0285 | N13: =IF(ISNUMBER(Annuität_Förderkredit),-Annuität_Förderkredit,0)*(A13<=Förderzeit) -> -7077.8193 | O13: =IF(L13>0,L13*M13,0) -> -345.94493 | P13: =IF(A13<=Anzahl_Tilgungszuschüsse,Tilgungszuschuss,0) -> 0 | Q13: =-N13+O13+P13 -> 6731.8743 | R13: =R12+Q13 -> 44593.456 | S13: =Q13+I13 -> 38866.039 | T13: =S13/(AuszahungKredit1+Förderkredit) -> 0.037078839 | U13: =S13+U12 -> 224525.1 | V13: =D13+L13 -> 862540.94 | X13: =X12*(1+Unterhaltskostensteigerung) -> -2223.7189 | Y13: =Y12*(1+Mietpreissteigerung_p.a.) -> 50054.425 | Z13: =IF(AfA_Art=AfA!B$15,VLOOKUP(A13,AfA_Tabelle,2),IF(AfA_Art=AfA!C$15,VLOOKUP(A13,AfA_Tabelle,3),IF(AfA_Art=AfA!D$15,VLOOKUP(A13,AfA_Tabelle,4),IF(AfA_Art=AfA!E$15,VLOOKUP(A13,AfA_Tabelle,5),IF(AfA_Art=AfA!F$15,VLOOKUP(A13,AfA_Tabelle,6),"tbd"))))) -> 0.02 | AA13: =IF(OR(AfA_Art=AfA!B$15,AfA_Art=AfA!C$15),-Z13*AD12,IF(OR(AfA_Art=AfA!D$15,AfA_Art=AfA!E$15,AfA_Art=AfA!F$15),AFABasis*-Z13,"check")) -> -18491.2 | AB13: 0 | AC13: =AA13+AB13 -> -18491.2 | AD13: =IF(AD12+AC13>=0,AD12+AC13,0) -> 813612.8 | AE13: =Y13+X13+G13+O13+AC13 -> 4757.0889 | AF13: =-Grenzsteuersatz -> -0.42 | AH13: =AE13*AF13 -> -1997.9774 | AI13: =Y13+X13+F13+H13+N13+P13 -> -15617.751 | AJ13: =AI13+AH13 -> -17615.728 | AK13: =+AJ13+AK12 -> -97976.732 | AM13: =AM12*(1+AM$6)+(AJ13/2)*AM$6+AJ13 -> -110987.46 | AN13: =+U13+AK13 -> 126548.37 | AO13: =+AM13+U13 -> 113537.65 | AQ13: =AQ12*(1+Wertzuwachst_des_Grundstücks_p.a.) -> 212304.03 | AR13: =AR12*(1-Wertverlust_des_Gebäudes_p.a.+Baukostensteigerung_p.a) -> 865517.11 | AS13: =AR13+AQ13 -> 1077821.1 | AT13: =(AS13-V13)*(V13>0) -> 215280.2 | AU13: =AS13+AN13-Investment -> 56169.509 | AW13: =AU13/Investment -> 0.048919621 | AX13: =(1+AW13)^(1/A13)-1 -> 0.0079918831 | AY13: =IF(Eigenkapital>0,AU13/Eigenkapital,"n/a") -> 0.56169509 | AZ13: =IF(Eigenkapital>0,(1+AY13)^(1/A13)-1,"n/a") -> 0.077124839 | BA13: =B13 -> 2031
A14: 7 | B14: =B13+1 -> 2032 | D14: =(A14<=FinZeitraum)*(D13-I13) -> 818268.35 | E14: =IF(A14<=LaufzeitKredit1,-Kreditzins1,IF(A14<=FinZeitraum,-Kreditzins2,0)) -> -0.0285 | F14: =IF(A14<=LaufzeitKredit1,-Annuität_Kredit_1_p.a.,IF(A14<=FinZeitraum,-Annuität_Kredit_2_p.a.,0)) -> -56370.637 | G14: =D14*E14 -> -23320.648 | H14: 0 | I14: =-F14+G14+H14 -> 33049.989 | J14: =J13+I14 -> 212981.64 | K14: =IF(D14>0,-I14/D$8,0) -> -0.033109586 | L14: =IF(L13-Q13<0,0,L13-Q13) -> 5406.5444 | M14: =IF(A14<=Förderzeit,-Förderzins,0) -> -0.0285 | N14: =IF(ISNUMBER(Annuität_Förderkredit),-Annuität_Förderkredit,0)*(A14<=Förderzeit) -> -7077.8193 | O14: =IF(L14>0,L14*M14,0) -> -154.08652 | P14: =IF(A14<=Anzahl_Tilgungszuschüsse,Tilgungszuschuss,0) -> 0 | Q14: =-N14+O14+P14 -> 6923.7328 | R14: =R13+Q14 -> 51517.188 | S14: =Q14+I14 -> 39973.722 | T14: =S14/(AuszahungKredit1+Förderkredit) -> 0.038135586 | U14: =S14+U13 -> 264498.82 | V14: =D14+L14 -> 823674.9 | X14: =X13*(1+Unterhaltskostensteigerung) -> -2251.5154 | Y14: =Y13*(1+Mietpreissteigerung_p.a.) -> 50680.105 | Z14: =IF(AfA_Art=AfA!B$15,VLOOKUP(A14,AfA_Tabelle,2),IF(AfA_Art=AfA!C$15,VLOOKUP(A14,AfA_Tabelle,3),IF(AfA_Art=AfA!D$15,VLOOKUP(A14,AfA_Tabelle,4),IF(AfA_Art=AfA!E$15,VLOOKUP(A14,AfA_Tabelle,5),IF(AfA_Art=AfA!F$15,VLOOKUP(A14,AfA_Tabelle,6),"tbd"))))) -> 0.02 | AA14: =IF(OR(AfA_Art=AfA!B$15,AfA_Art=AfA!C$15),-Z14*RBWnach6Jahren*(A14>=7),IF(OR(AfA_Art=AfA!D$15,AfA_Art=AfA!E$15,AfA_Art=AfA!F$15),AFABasis*-Z14,"check")) -> -18491.2 | AB14: 0 | AC14: =AA14+AB14 -> -18491.2 | AD14: =IF(AD13+AC14>=0,AD13+AC14,0) -> 795121.6 | AE14: =Y14+X14+G14+O14+AC14 -> 6462.6549 | AF14: =-Grenzsteuersatz -> -0.42 | AH14: =AE14*AF14 -> -2714.3151 | AI14: =Y14+X14+F14+H14+N14+P14 -> -15019.867 | AJ14: =AI14+AH14 -> -17734.182 | AK14: =+AJ14+AK13 -> -115710.91 | AM14: =AM13*(1+AM$6)+(AJ14/2)*AM$6+AJ14 -> -133726.77 | AN14: =+U14+AK14 -> 148787.91 | AO14: =+AM14+U14 -> 130772.06 | AQ14: =AQ13*(1+Wertzuwachst_des_Grundstücks_p.a.) -> 214427.07 | AR14: =AR13*(1-Wertverlust_des_Gebäudes_p.a.+Baukostensteigerung_p.a) -> 869844.69 | AS14: =AR14+AQ14 -> 1084271.8 | AT14: =(AS14-V14)*(V14>0) -> 260596.87 | AU14: =AS14+AN14-Investment -> 84859.675 | AW14: =AU14/Investment -> 0.073906702 | AX14: =(1+AW14)^(1/A14)-1 -> 0.010238216 | AY14: =IF(Eigenkapital>0,AU14/Eigenkapital,"n/a") -> 0.84859675 | AZ14: =IF(Eigenkapital>0,(1+AY14)^(1/A14)-1,"n/a") -> 0.091742739 | BA14: =B14 -> 2032
A15: 8 | B15: =B14+1 -> 2033 | D15: =(A15<=FinZeitraum)*(D14-I14) -> 785218.36 | E15: =IF(A15<=LaufzeitKredit1,-Kreditzins1,IF(A15<=FinZeitraum,-Kreditzins2,0)) -> -0.0285 | F15: =IF(A15<=LaufzeitKredit1,-Annuität_Kredit_1_p.a.,IF(A15<=FinZeitraum,-Annuität_Kredit_2_p.a.,0)) -> -56370.637 | G15: =D15*E15 -> -22378.723 | H15: 0 | I15: =-F15+G15+H15 -> 33991.913 | J15: =J14+I15 -> 246973.55 | K15: =IF(D15>0,-I15/D$8,0) -> -0.034053209 | L15: =IF(L14-Q14<0,0,L14-Q14) -> 0 | M15: =IF(A15<=Förderzeit,-Förderzins,0) -> -0.0285 | N15: =IF(ISNUMBER(Annuität_Förderkredit),-Annuität_Förderkredit,0)*(A15<=Förderzeit) -> -7077.8193 | O15: =IF(L15>0,L15*M15,0) -> 0 | P15: =IF(A15<=Anzahl_Tilgungszuschüsse,Tilgungszuschuss,0) -> 0 | Q15: =-N15+O15+P15 -> 7077.8193 | R15: =R14+Q15 -> 58595.008 | S15: =Q15+I15 -> 41069.733 | T15: =S15/(AuszahungKredit1+Förderkredit) -> 0.039181199 | U15: =S15+U14 -> 305568.56 | V15: =D15+L15 -> 785218.36 | X15: =X14*(1+Unterhaltskostensteigerung) -> -2279.6593 | Y15: =Y14*(1+Mietpreissteigerung_p.a.) -> 51313.606 | Z15: =IF(AfA_Art=AfA!B$15,VLOOKUP(A15,AfA_Tabelle,2),IF(AfA_Art=AfA!C$15,VLOOKUP(A15,AfA_Tabelle,3),IF(AfA_Art=AfA!D$15,VLOOKUP(A15,AfA_Tabelle,4),IF(AfA_Art=AfA!E$15,VLOOKUP(A15,AfA_Tabelle,5),IF(AfA_Art=AfA!F$15,VLOOKUP(A15,AfA_Tabelle,6),"tbd"))))) -> 0.02 | AA15: =IF(OR(AfA_Art=AfA!B$15,AfA_Art=AfA!C$15),-Z15*RBWnach6Jahren*(A15>=7),IF(OR(AfA_Art=AfA!D$15,AfA_Art=AfA!E$15,AfA_Art=AfA!F$15),AFABasis*-Z15,"check")) -> -18491.2 | AB15: 0 | AC15: =AA15+AB15 -> -18491.2 | AD15: =IF(AD14+AC15>=0,AD14+AC15,0) -> 776630.4 | AE15: =Y15+X15+G15+O15+AC15 -> 8164.0234 | AF15: =-Grenzsteuersatz -> -0.42 | AH15: =AE15*AF15 -> -3428.8898 | AI15: =Y15+X15+F15+H15+N15+P15 -> -14414.509 | AJ15: =AI15+AH15 -> -17843.399 | AK15: =+AJ15+AK14 -> -133554.31 | AM15: =AM14*(1+AM$6)+(AJ15/2)*AM$6+AJ15 -> -157527.16 | AN15: =+U15+AK15 -> 172014.24 | AO15: =+AM15+U15 -> 148041.39 | AQ15: =AQ14*(1+Wertzuwachst_des_Grundstücks_p.a.) -> 216571.34 | AR15: =AR14*(1-Wertverlust_des_Gebäudes_p.a.+Baukostensteigerung_p.a) -> 874193.92 | AS15: =AR15+AQ15 -> 1090765.3 | AT15: =(AS15-V15)*(V15>0) -> 305546.89 | AU15: =AS15+AN15-Investment -> 114579.5 | AW15: =AU15/Investment -> 0.099790544 | AX15: =(1+AW15)^(1/A15)-1 -> 0.011960935 | AY15: =IF(Eigenkapital>0,AU15/Eigenkapital,"n/a") -> 1.145795 | AZ15: =IF(Eigenkapital>0,(1+AY15)^(1/A15)-1,"n/a") -> 0.10014145 | BA15: =B15 -> 2033
A16: 9 | B16: =B15+1 -> 2034 | D16: =(A16<=FinZeitraum)*(D15-I15) -> 751226.45 | E16: =IF(A16<=LaufzeitKredit1,-Kreditzins1,IF(A16<=FinZeitraum,-Kreditzins2,0)) -> -0.0285 | F16: =IF(A16<=LaufzeitKredit1,-Annuität_Kredit_1_p.a.,IF(A16<=FinZeitraum,-Annuität_Kredit_2_p.a.,0)) -> -56370.637 | G16: =D16*E16 -> -21409.954 | H16: 0 | I16: =-F16+G16+H16 -> 34960.683 | J16: =J15+I16 -> 281934.23 | K16: =IF(D16>0,-I16/D$8,0) -> -0.035023726 | L16: =IF(L15-Q15<0,0,L15-Q15) -> 0 | M16: =IF(A16<=Förderzeit,-Förderzins,0) -> 0 | N16: =IF(ISNUMBER(Annuität_Förderkredit),-Annuität_Förderkredit,0)*(A16<=Förderzeit) -> 0 | O16: =IF(L16>0,L16*M16,0) -> 0 | P16: =IF(A16<=Anzahl_Tilgungszuschüsse,Tilgungszuschuss,0) -> 0 | Q16: =-N16+O16+P16 -> 0 | R16: =R15+Q16 -> 58595.008 | S16: =Q16+I16 -> 34960.683 | T16: =S16/(AuszahungKredit1+Förderkredit) -> 0.033353065 | U16: =S16+U15 -> 340529.24 | V16: =D16+L16 -> 751226.45 | X16: =X15*(1+Unterhaltskostensteigerung) -> -2308.1551 | Y16: =Y15*(1+Mietpreissteigerung_p.a.) -> 51955.026 | Z16: =IF(AfA_Art=AfA!B$15,VLOOKUP(A16,AfA_Tabelle,2),IF(AfA_Art=AfA!C$15,VLOOKUP(A16,AfA_Tabelle,3),IF(AfA_Art=AfA!D$15,VLOOKUP(A16,AfA_Tabelle,4),IF(AfA_Art=AfA!E$15,VLOOKUP(A16,AfA_Tabelle,5),IF(AfA_Art=AfA!F$15,VLOOKUP(A16,AfA_Tabelle,6),"tbd"))))) -> 0.02 | AA16: =IF(OR(AfA_Art=AfA!B$15,AfA_Art=AfA!C$15),-Z16*RBWnach6Jahren*(A16>=7),IF(OR(AfA_Art=AfA!D$15,AfA_Art=AfA!E$15,AfA_Art=AfA!F$15),AFABasis*-Z16,"check")) -> -18491.2 | AB16: 0 | AC16: =AA16+AB16 -> -18491.2 | AD16: =IF(AD15+AC16>=0,AD15+AC16,0) -> 758139.2 | AE16: =Y16+X16+G16+O16+AC16 -> 9745.7173 | AF16: =-Grenzsteuersatz -> -0.42 | AH16: =AE16*AF16 -> -4093.2013 | AI16: =Y16+X16+F16+H16+N16+P16 -> -6723.7657 | AJ16: =AI16+AH16 -> -10816.967 | AK16: =+AJ16+AK15 -> -144371.28 | AM16: =AM15*(1+AM$6)+(AJ16/2)*AM$6+AJ16 -> -175148.32 | AN16: =+U16+AK16 -> 196157.96 | AO16: =+AM16+U16 -> 165380.92 | AQ16: =AQ15*(1+Wertzuwachst_des_Grundstücks_p.a.) -> 218737.05 | AR16: =AR15*(1-Wertverlust_des_Gebäudes_p.a.+Baukostensteigerung_p.a) -> 878564.89 | AS16: =AR16+AQ16 -> 1097301.9 | AT16: =(AS16-V16)*(V16>0) -> 346075.49 | AU16: =AS16+AN16-Investment -> 145259.9 | AW16: =AU16/Investment -> 0.12651098 | AX16: =(1+AW16)^(1/A16)-1 -> 0.013324121 | AY16: =IF(Eigenkapital>0,AU16/Eigenkapital,"n/a") -> 1.452599 | AZ16: =IF(Eigenkapital>0,(1+AY16)^(1/A16)-1,"n/a") -> 0.10482079 | BA16: =B16 -> 2034
A17: 10 | B17: =B16+1 -> 2035 | D17: =(A17<=FinZeitraum)*(D16-I16) -> 716265.77 | E17: =IF(A17<=LaufzeitKredit1,-Kreditzins1,IF(A17<=FinZeitraum,-Kreditzins2,0)) -> -0.0285 | F17: =IF(A17<=LaufzeitKredit1,-Annuität_Kredit_1_p.a.,IF(A17<=FinZeitraum,-Annuität_Kredit_2_p.a.,0)) -> -56370.637 | G17: =D17*E17 -> -20413.574 | H17: 0 | I17: =-F17+G17+H17 -> 35957.062 | J17: =J16+I17 -> 317891.3 | K17: =IF(D17>0,-I17/D$8,0) -> -0.036021902 | L17: =IF(L16-Q16<0,0,L16-Q16) -> 0 | M17: =IF(A17<=Förderzeit,-Förderzins,0) -> 0 | N17: =IF(ISNUMBER(Annuität_Förderkredit),-Annuität_Förderkredit,0)*(A17<=Förderzeit) -> 0 | O17: =IF(L17>0,L17*M17,0) -> 0 | P17: =IF(A17<=Anzahl_Tilgungszuschüsse,Tilgungszuschuss,0) -> 0 | Q17: =-N17+O17+P17 -> 0 | R17: =R16+Q17 -> 58595.008 | S17: =Q17+I17 -> 35957.062 | T17: =S17/(AuszahungKredit1+Förderkredit) -> 0.034303628 | U17: =S17+U16 -> 376486.3 | V17: =D17+L17 -> 716265.77 | X17: =X16*(1+Unterhaltskostensteigerung) -> -2337.007 | Y17: =Y16*(1+Mietpreissteigerung_p.a.) -> 52604.464 | Z17: =IF(AfA_Art=AfA!B$15,VLOOKUP(A17,AfA_Tabelle,2),IF(AfA_Art=AfA!C$15,VLOOKUP(A17,AfA_Tabelle,3),IF(AfA_Art=AfA!D$15,VLOOKUP(A17,AfA_Tabelle,4),IF(AfA_Art=AfA!E$15,VLOOKUP(A17,AfA_Tabelle,5),IF(AfA_Art=AfA!F$15,VLOOKUP(A17,AfA_Tabelle,6),"tbd"))))) -> 0.02 | AA17: =IF(OR(AfA_Art=AfA!B$15,AfA_Art=AfA!C$15),-Z17*RBWnach6Jahren*(A17>=7),IF(OR(AfA_Art=AfA!D$15,AfA_Art=AfA!E$15,AfA_Art=AfA!F$15),AFABasis*-Z17,"check")) -> -18491.2 | AB17: 0 | AC17: =AA17+AB17 -> -18491.2 | AD17: =IF(AD16+AC17>=0,AD16+AC17,0) -> 739648 | AE17: =Y17+X17+G17+O17+AC17 -> 11362.683 | AF17: =-Grenzsteuersatz -> -0.42 | AH17: =AE17*AF17 -> -4772.3267 | AI17: =Y17+X17+F17+H17+N17+P17 -> -6103.1798 | AJ17: =AI17+AH17 -> -10875.507 | AK17: =+AJ17+AK16 -> -155246.79 | AM17: =AM16*(1+AM$6)+(AJ17/2)*AM$6+AJ17 -> -193565.11 | AN17: =+U17+AK17 -> 221239.52 | AO17: =+AM17+U17 -> 182921.2 | AQ17: =AQ16*(1+Wertzuwachst_des_Grundstücks_p.a.) -> 220924.43 | AR17: =AR16*(1-Wertverlust_des_Gebäudes_p.a.+Baukostensteigerung_p.a) -> 882957.71 | AS17: =AR17+AQ17 -> 1103882.1 | AT17: =(AS17-V17)*(V17>0) -> 387616.37 | AU17: =AS17+AN17-Investment -> 176921.65 | AW17: =AU17/Investment -> 0.15408609 | AX17: =(1+AW17)^(1/A17)-1 -> 0.014434056 | AY17: =IF(Eigenkapital>0,AU17/Eigenkapital,"n/a") -> 1.7692165 | AZ17: =IF(Eigenkapital>0,(1+AY17)^(1/A17)-1,"n/a") -> 0.10722451 | BA17: =B17 -> 2035
A18: 11 | B18: =B17+1 -> 2036 | D18: =(A18<=FinZeitraum)*(D17-I17) -> 680308.7 | E18: =IF(A18<=LaufzeitKredit1,-Kreditzins1,IF(A18<=FinZeitraum,-Kreditzins2,0)) -> -0.0325 | F18: =IF(A18<=LaufzeitKredit1,-Annuität_Kredit_1_p.a.,IF(A18<=FinZeitraum,-Annuität_Kredit_2_p.a.,0)) -> -58022.563 | G18: =D18*E18 -> -22110.033 | H18: 0 | I18: =-F18+G18+H18 -> 35912.53 | J18: =J17+I18 -> 353803.83 | K18: =IF(D18>0,-I18/D$8,0) -> -0.035977289 | L18: =IF(L17-Q17<0,0,L17-Q17) -> 0 | M18: =IF(A18<=Förderzeit,-Förderzins,0) -> 0 | N18: =IF(ISNUMBER(Annuität_Förderkredit),-Annuität_Förderkredit,0)*(A18<=Förderzeit) -> 0 | O18: =IF(L18>0,L18*M18,0) -> 0 | P18: =IF(A18<=Anzahl_Tilgungszuschüsse,Tilgungszuschuss,0) -> 0 | Q18: =-N18+O18+P18 -> 0 | R18: =R17+Q18 -> 58595.008 | S18: =Q18+I18 -> 35912.53 | T18: =S18/(AuszahungKredit1+Förderkredit) -> 0.034261143 | U18: =S18+U17 -> 412398.83 | V18: =D18+L18 -> 680308.7 | X18: =X17*(1+Unterhaltskostensteigerung) -> -2366.2196 | Y18: =Y17*(1+Mietpreissteigerung_p.a.) -> 53262.02 | Z18: =IF(AfA_Art=AfA!B$15,VLOOKUP(A18,AfA_Tabelle,2),IF(AfA_Art=AfA!C$15,VLOOKUP(A18,AfA_Tabelle,3),IF(AfA_Art=AfA!D$15,VLOOKUP(A18,AfA_Tabelle,4),IF(AfA_Art=AfA!E$15,VLOOKUP(A18,AfA_Tabelle,5),IF(AfA_Art=AfA!F$15,VLOOKUP(A18,AfA_Tabelle,6),"tbd"))))) -> 0.02 | AA18: =IF(OR(AfA_Art=AfA!B$15,AfA_Art=AfA!C$15),-Z18*RBWnach6Jahren*(A18>=7),IF(OR(AfA_Art=AfA!D$15,AfA_Art=AfA!E$15,AfA_Art=AfA!F$15),AFABasis*-Z18,"check")) -> -18491.2 | AB18: 0 | AC18: =AA18+AB18 -> -18491.2 | AD18: =IF(AD17+AC18>=0,AD17+AC18,0) -> 721156.8 | AE18: =Y18+X18+G18+O18+AC18 -> 10294.567 | AF18: =-Grenzsteuersatz -> -0.42 | AH18: =AE18*AF18 -> -4323.7183 | AI18: =Y18+X18+F18+H18+N18+P18 -> -7126.7629 | AJ18: =AI18+AH18 -> -11450.481 | AK18: =+AJ18+AK17 -> -166697.27 | AM18: =AM17*(1+AM$6)+(AJ18/2)*AM$6+AJ18 -> -213337.95 | AN18: =+U18+AK18 -> 245701.57 | AO18: =+AM18+U18 -> 199060.88 | AQ18: =AQ17*(1+Wertzuwachst_des_Grundstücks_p.a.) -> 223133.67 | AR18: =AR17*(1-Wertverlust_des_Gebäudes_p.a.+Baukostensteigerung_p.a) -> 887372.5 | AS18: =AR18+AQ18 -> 1110506.2 | AT18: =(AS18-V18)*(V18>0) -> 430197.46 | AU18: =AS18+AN18-Investment -> 208007.73 | AW18: =AU18/Investment -> 0.18115985 | AX18: =(1+AW18)^(1/A18)-1 -> 0.01525121 | AY18: =IF(Eigenkapital>0,AU18/Eigenkapital,"n/a") -> 2.0800773 | AZ18: =IF(Eigenkapital>0,(1+AY18)^(1/A18)-1,"n/a") -> 0.10768097 | BA18: =B18 -> 2036
A19: 12 | B19: =B18+1 -> 2037 | D19: =(A19<=FinZeitraum)*(D18-I18) -> 644396.17 | E19: =IF(A19<=LaufzeitKredit1,-Kreditzins1,IF(A19<=FinZeitraum,-Kreditzins2,0)) -> -0.0325 | F19: =IF(A19<=LaufzeitKredit1,-Annuität_Kredit_1_p.a.,IF(A19<=FinZeitraum,-Annuität_Kredit_2_p.a.,0)) -> -58022.563 | G19: =D19*E19 -> -20942.876 | H19: 0 | I19: =-F19+G19+H19 -> 37079.688 | J19: =J18+I19 -> 390883.51 | K19: =IF(D19>0,-I19/D$8,0) -> -0.037146551 | L19: =IF(L18-Q18<0,0,L18-Q18) -> 0 | M19: =IF(A19<=Förderzeit,-Förderzins,0) -> 0 | N19: =IF(ISNUMBER(Annuität_Förderkredit),-Annuität_Förderkredit,0)*(A19<=Förderzeit) -> 0 | O19: =IF(L19>0,L19*M19,0) -> 0 | P19: =IF(A19<=Anzahl_Tilgungszuschüsse,Tilgungszuschuss,0) -> 0 | Q19: =-N19+O19+P19 -> 0 | R19: =R18+Q19 -> 58595.008 | S19: =Q19+I19 -> 37079.688 | T19: =S19/(AuszahungKredit1+Förderkredit) -> 0.03537463 | U19: =S19+U18 -> 449478.52 | V19: =D19+L19 -> 644396.17 | X19: =X18*(1+Unterhaltskostensteigerung) -> -2395.7973 | Y19: =Y18*(1+Mietpreissteigerung_p.a.) -> 53927.795 | Z19: =IF(AfA_Art=AfA!B$15,VLOOKUP(A19,AfA_Tabelle,2),IF(AfA_Art=AfA!C$15,VLOOKUP(A19,AfA_Tabelle,3),IF(AfA_Art=AfA!D$15,VLOOKUP(A19,AfA_Tabelle,4),IF(AfA_Art=AfA!E$15,VLOOKUP(A19,AfA_Tabelle,5),IF(AfA_Art=AfA!F$15,VLOOKUP(A19,AfA_Tabelle,6),"tbd"))))) -> 0.02 | AA19: =IF(OR(AfA_Art=AfA!B$15,AfA_Art=AfA!C$15),-Z19*RBWnach6Jahren*(A19>=7),IF(OR(AfA_Art=AfA!D$15,AfA_Art=AfA!E$15,AfA_Art=AfA!F$15),AFABasis*-Z19,"check")) -> -18491.2 | AB19: 0 | AC19: =AA19+AB19 -> -18491.2 | AD19: =IF(AD18+AC19>=0,AD18+AC19,0) -> 702665.6 | AE19: =Y19+X19+G19+O19+AC19 -> 12097.922 | AF19: =-Grenzsteuersatz -> -0.42 | AH19: =AE19*AF19 -> -5081.1273 | AI19: =Y19+X19+F19+H19+N19+P19 -> -6490.5654 | AJ19: =AI19+AH19 -> -11571.693 | AK19: =+AJ19+AK18 -> -178268.96 | AM19: =AM18*(1+AM$6)+(AJ19/2)*AM$6+AJ19 -> -234060.25 | AN19: =+U19+AK19 -> 271209.56 | AO19: =+AM19+U19 -> 215418.27 | AQ19: =AQ18*(1+Wertzuwachst_des_Grundstücks_p.a.) -> 225365.01 | AR19: =AR18*(1-Wertverlust_des_Gebäudes_p.a.+Baukostensteigerung_p.a) -> 891809.36 | AS19: =AR19+AQ19 -> 1117174.4 | AT19: =(AS19-V19)*(V19>0) -> 472778.19 | AU19: =AS19+AN19-Investment -> 240183.93 | AW19: =AU19/Investment -> 0.20918301 | AX19: =(1+AW19)^(1/A19)-1 -> 0.015954682 | AY19: =IF(Eigenkapital>0,AU19/Eigenkapital,"n/a") -> 2.4018393 | AZ19: =IF(Eigenkapital>0,(1+AY19)^(1/A19)-1,"n/a") -> 0.10741266 | BA19: =B19 -> 2037
A20: 13 | B20: =B19+1 -> 2038 | D20: =(A20<=FinZeitraum)*(D19-I19) -> 607316.49 | E20: =IF(A20<=LaufzeitKredit1,-Kreditzins1,IF(A20<=FinZeitraum,-Kreditzins2,0)) -> -0.0325 | F20: =IF(A20<=LaufzeitKredit1,-Annuität_Kredit_1_p.a.,IF(A20<=FinZeitraum,-Annuität_Kredit_2_p.a.,0)) -> -58022.563 | G20: =D20*E20 -> -19737.786 | H20: 0 | I20: =-F20+G20+H20 -> 38284.777 | J20: =J19+I20 -> 429168.29 | K20: =IF(D20>0,-I20/D$8,0) -> -0.038353814 | L20: =IF(L19-Q19<0,0,L19-Q19) -> 0 | M20: =IF(A20<=Förderzeit,-Förderzins,0) -> 0 | N20: =IF(ISNUMBER(Annuität_Förderkredit),-Annuität_Förderkredit,0)*(A20<=Förderzeit) -> 0 | O20: =IF(L20>0,L20*M20,0) -> 0 | P20: =IF(A20<=Anzahl_Tilgungszuschüsse,Tilgungszuschuss,0) -> 0 | Q20: =-N20+O20+P20 -> 0 | R20: =R19+Q20 -> 58595.008 | S20: =Q20+I20 -> 38284.777 | T20: =S20/(AuszahungKredit1+Förderkredit) -> 0.036524306 | U20: =S20+U19 -> 487763.3 | V20: =D20+L20 -> 607316.49 | X20: =X19*(1+Unterhaltskostensteigerung) -> -2425.7448 | Y20: =Y19*(1+Mietpreissteigerung_p.a.) -> 54601.893 | Z20: =IF(AfA_Art=AfA!B$15,VLOOKUP(A20,AfA_Tabelle,2),IF(AfA_Art=AfA!C$15,VLOOKUP(A20,AfA_Tabelle,3),IF(AfA_Art=AfA!D$15,VLOOKUP(A20,AfA_Tabelle,4),IF(AfA_Art=AfA!E$15,VLOOKUP(A20,AfA_Tabelle,5),IF(AfA_Art=AfA!F$15,VLOOKUP(A20,AfA_Tabelle,6),"tbd"))))) -> 0.02 | AA20: =IF(OR(AfA_Art=AfA!B$15,AfA_Art=AfA!C$15),-Z20*RBWnach6Jahren*(A20>=7),IF(OR(AfA_Art=AfA!D$15,AfA_Art=AfA!E$15,AfA_Art=AfA!F$15),AFABasis*-Z20,"check")) -> -18491.2 | AB20: 0 | AC20: =AA20+AB20 -> -18491.2 | AD20: =IF(AD19+AC20>=0,AD19+AC20,0) -> 684174.4 | AE20: =Y20+X20+G20+O20+AC20 -> 13947.162 | AF20: =-Grenzsteuersatz -> -0.42 | AH20: =AE20*AF20 -> -5857.808 | AI20: =Y20+X20+F20+H20+N20+P20 -> -5846.4155 | AJ20: =AI20+AH20 -> -11704.223 | AK20: =+AJ20+AK19 -> -189973.18 | AM20: =AM19*(1+AM$6)+(AJ20/2)*AM$6+AJ20 -> -255783.22 | AN20: =+U20+AK20 -> 297790.11 | AO20: =+AM20+U20 -> 231980.08 | AQ20: =AQ19*(1+Wertzuwachst_des_Grundstücks_p.a.) -> 227618.66 | AR20: =AR19*(1-Wertverlust_des_Gebäudes_p.a.+Baukostensteigerung_p.a) -> 896268.41 | AS20: =AR20+AQ20 -> 1123887.1 | AT20: =(AS20-V20)*(V20>0) -> 516570.58 | AU20: =AS20+AN20-Investment -> 273477.18 | AW20: =AU20/Investment -> 0.23817904 | AX20: =(1+AW20)^(1/A20)-1 -> 0.016569764 | AY20: =IF(Eigenkapital>0,AU20/Eigenkapital,"n/a") -> 2.7347718 | AZ20: =IF(Eigenkapital>0,(1+AY20)^(1/A20)-1,"n/a") -> 0.10667554 | BA20: =B20 -> 2038
A21: 14 | B21: =B20+1 -> 2039 | D21: =(A21<=FinZeitraum)*(D20-I20) -> 569031.71 | E21: =IF(A21<=LaufzeitKredit1,-Kreditzins1,IF(A21<=FinZeitraum,-Kreditzins2,0)) -> -0.0325 | F21: =IF(A21<=LaufzeitKredit1,-Annuität_Kredit_1_p.a.,IF(A21<=FinZeitraum,-Annuität_Kredit_2_p.a.,0)) -> -58022.563 | G21: =D21*E21 -> -18493.531 | H21: 0 | I21: =-F21+G21+H21 -> 39529.033 | J21: =J20+I21 -> 468697.32 | K21: =IF(D21>0,-I21/D$8,0) -> -0.039600313 | L21: =IF(L20-Q20<0,0,L20-Q20) -> 0 | M21: =IF(A21<=Förderzeit,-Förderzins,0) -> 0 | N21: =IF(ISNUMBER(Annuität_Förderkredit),-Annuität_Förderkredit,0)*(A21<=Förderzeit) -> 0 | O21: =IF(L21>0,L21*M21,0) -> 0 | P21: =IF(A21<=Anzahl_Tilgungszuschüsse,Tilgungszuschuss,0) -> 0 | Q21: =-N21+O21+P21 -> 0 | R21: =R20+Q21 -> 58595.008 | S21: =Q21+I21 -> 39529.033 | T21: =S21/(AuszahungKredit1+Förderkredit) -> 0.037711346 | U21: =S21+U20 -> 527292.33 | V21: =D21+L21 -> 569031.71 | X21: =X20*(1+Unterhaltskostensteigerung) -> -2456.0666 | Y21: =Y20*(1+Mietpreissteigerung_p.a.) -> 55284.416 | Z21: =IF(AfA_Art=AfA!B$15,VLOOKUP(A21,AfA_Tabelle,2),IF(AfA_Art=AfA!C$15,VLOOKUP(A21,AfA_Tabelle,3),IF(AfA_Art=AfA!D$15,VLOOKUP(A21,AfA_Tabelle,4),IF(AfA_Art=AfA!E$15,VLOOKUP(A21,AfA_Tabelle,5),IF(AfA_Art=AfA!F$15,VLOOKUP(A21,AfA_Tabelle,6),"tbd"))))) -> 0.02 | AA21: =IF(OR(AfA_Art=AfA!B$15,AfA_Art=AfA!C$15),-Z21*RBWnach6Jahren*(A21>=7),IF(OR(AfA_Art=AfA!D$15,AfA_Art=AfA!E$15,AfA_Art=AfA!F$15),AFABasis*-Z21,"check")) -> -18491.2 | AB21: 0 | AC21: =AA21+AB21 -> -18491.2 | AD21: =IF(AD20+AC21>=0,AD20+AC21,0) -> 665683.2 | AE21: =Y21+X21+G21+O21+AC21 -> 15843.619 | AF21: =-Grenzsteuersatz -> -0.42 | AH21: =AE21*AF21 -> -6654.32 | AI21: =Y21+X21+F21+H21+N21+P21 -> -5194.2136 | AJ21: =AI21+AH21 -> -11848.534 | AK21: =+AJ21+AK20 -> -201821.72 | AM21: =AM20*(1+AM$6)+(AJ21/2)*AM$6+AJ21 -> -278560.66 | AN21: =+U21+AK21 -> 325470.61 | AO21: =+AM21+U21 -> 248731.68 | AQ21: =AQ20*(1+Wertzuwachst_des_Grundstücks_p.a.) -> 229894.84 | AR21: =AR20*(1-Wertverlust_des_Gebäudes_p.a.+Baukostensteigerung_p.a) -> 900749.75 | AS21: =AR21+AQ21 -> 1130644.6 | AT21: =(AS21-V21)*(V21>0) -> 561612.88 | AU21: =AS21+AN21-Investment -> 307915.21 | AW21: =AU21/Investment -> 0.2681721 | AX21: =(1+AW21)^(1/A21)-1 -> 0.017114559 | AY21: =IF(Eigenkapital>0,AU21/Eigenkapital,"n/a") -> 3.0791521 | AZ21: =IF(Eigenkapital>0,(1+AY21)^(1/A21)-1,"n/a") -> 0.10563591 | BA21: =B21 -> 2039
A22: 15 | B22: =B21+1 -> 2040 | D22: =(A22<=FinZeitraum)*(D21-I21) -> 529502.68 | E22: =IF(A22<=LaufzeitKredit1,-Kreditzins1,IF(A22<=FinZeitraum,-Kreditzins2,0)) -> -0.0325 | F22: =IF(A22<=LaufzeitKredit1,-Annuität_Kredit_1_p.a.,IF(A22<=FinZeitraum,-Annuität_Kredit_2_p.a.,0)) -> -58022.563 | G22: =D22*E22 -> -17208.837 | H22: 0 | I22: =-F22+G22+H22 -> 40813.726 | J22: =J21+I22 -> 509511.05 | K22: =IF(D22>0,-I22/D$8,0) -> -0.040887323 | L22: =IF(L21-Q21<0,0,L21-Q21) -> 0 | M22: =IF(A22<=Förderzeit,-Förderzins,0) -> 0 | N22: =IF(ISNUMBER(Annuität_Förderkredit),-Annuität_Förderkredit,0)*(A22<=Förderzeit) -> 0 | O22: =IF(L22>0,L22*M22,0) -> 0 | P22: =IF(A22<=Anzahl_Tilgungszuschüsse,Tilgungszuschuss,0) -> 0 | Q22: =-N22+O22+P22 -> 0 | R22: =R21+Q22 -> 58595.008 | S22: =Q22+I22 -> 40813.726 | T22: =S22/(AuszahungKredit1+Förderkredit) -> 0.038936964 | U22: =S22+U21 -> 568106.06 | V22: =D22+L22 -> 529502.68 | X22: =X21*(1+Unterhaltskostensteigerung) -> -2486.7674 | Y22: =Y21*(1+Mietpreissteigerung_p.a.) -> 55975.471 | Z22: =IF(AfA_Art=AfA!B$15,VLOOKUP(A22,AfA_Tabelle,2),IF(AfA_Art=AfA!C$15,VLOOKUP(A22,AfA_Tabelle,3),IF(AfA_Art=AfA!D$15,VLOOKUP(A22,AfA_Tabelle,4),IF(AfA_Art=AfA!E$15,VLOOKUP(A22,AfA_Tabelle,5),IF(AfA_Art=AfA!F$15,VLOOKUP(A22,AfA_Tabelle,6),"tbd"))))) -> 0.02 | AA22: =IF(OR(AfA_Art=AfA!B$15,AfA_Art=AfA!C$15),-Z22*RBWnach6Jahren*(A22>=7),IF(OR(AfA_Art=AfA!D$15,AfA_Art=AfA!E$15,AfA_Art=AfA!F$15),AFABasis*-Z22,"check")) -> -18491.2 | AB22: 0 | AC22: =AA22+AB22 -> -18491.2 | AD22: =IF(AD21+AC22>=0,AD21+AC22,0) -> 647192 | AE22: =Y22+X22+G22+O22+AC22 -> 17788.667 | AF22: =-Grenzsteuersatz -> -0.42 | AH22: =AE22*AF22 -> -7471.2401 | AI22: =Y22+X22+F22+H22+N22+P22 -> -4533.8592 | AJ22: =AI22+AH22 -> -12005.099 | AK22: =+AJ22+AK21 -> -213826.82 | AM22: =AM21*(1+AM$6)+(AJ22/2)*AM$6+AJ22 -> -302449.11 | AN22: =+U22+AK22 -> 354279.24 | AO22: =+AM22+U22 -> 265656.94 | AQ22: =AQ21*(1+Wertzuwachst_des_Grundstücks_p.a.) -> 232193.79 | AR22: =AR21*(1-Wertverlust_des_Gebäudes_p.a.+Baukostensteigerung_p.a) -> 905253.5 | AS22: =AR22+AQ22 -> 1137447.3 | AT22: =(AS22-V22)*(V22>0) -> 607944.61 | AU22: =AS22+AN22-Investment -> 343526.53 | AW22: =AU22/Investment -> 0.29918702 | AX22: =(1+AW22)^(1/A22)-1 -> 0.017602374 | AY22: =IF(Eigenkapital>0,AU22/Eigenkapital,"n/a") -> 3.4352653 | AZ22: =IF(Eigenkapital>0,(1+AY22)^(1/A22)-1,"n/a") -> 0.10440401 | BA22: =B22 -> 2040
A23: 16 | B23: =B22+1 -> 2041 | D23: =(A23<=FinZeitraum)*(D22-I22) -> 488688.95 | E23: =IF(A23<=LaufzeitKredit1,-Kreditzins1,IF(A23<=FinZeitraum,-Kreditzins2,0)) -> -0.0325 | F23: =IF(A23<=LaufzeitKredit1,-Annuität_Kredit_1_p.a.,IF(A23<=FinZeitraum,-Annuität_Kredit_2_p.a.,0)) -> -58022.563 | G23: =D23*E23 -> -15882.391 | H23: 0 | I23: =-F23+G23+H23 -> 42140.172 | J23: =J22+I23 -> 551651.22 | K23: =IF(D23>0,-I23/D$8,0) -> -0.042216161 | L23: =IF(L22-Q22<0,0,L22-Q22) -> 0 | M23: =IF(A23<=Förderzeit,-Förderzins,0) -> 0 | N23: =IF(ISNUMBER(Annuität_Förderkredit),-Annuität_Förderkredit,0)*(A23<=Förderzeit) -> 0 | O23: =IF(L23>0,L23*M23,0) -> 0 | P23: =IF(A23<=Anzahl_Tilgungszuschüsse,Tilgungszuschuss,0) -> 0 | Q23: =-N23+O23+P23 -> 0 | R23: =R22+Q23 -> 58595.008 | S23: =Q23+I23 -> 42140.172 | T23: =S23/(AuszahungKredit1+Förderkredit) -> 0.040202416 | U23: =S23+U22 -> 610246.23 | V23: =D23+L23 -> 488688.95 | X23: =X22*(1+Unterhaltskostensteigerung) -> -2517.852 | Y23: =Y22*(1+Mietpreissteigerung_p.a.) -> 56675.165 | Z23: =IF(AfA_Art=AfA!B$15,VLOOKUP(A23,AfA_Tabelle,2),IF(AfA_Art=AfA!C$15,VLOOKUP(A23,AfA_Tabelle,3),IF(AfA_Art=AfA!D$15,VLOOKUP(A23,AfA_Tabelle,4),IF(AfA_Art=AfA!E$15,VLOOKUP(A23,AfA_Tabelle,5),IF(AfA_Art=AfA!F$15,VLOOKUP(A23,AfA_Tabelle,6),"tbd"))))) -> 0.02 | AA23: =IF(OR(AfA_Art=AfA!B$15,AfA_Art=AfA!C$15),-Z23*RBWnach6Jahren*(A23>=7),IF(OR(AfA_Art=AfA!D$15,AfA_Art=AfA!E$15,AfA_Art=AfA!F$15),AFABasis*-Z23,"check")) -> -18491.2 | AB23: 0 | AC23: =AA23+AB23 -> -18491.2 | AD23: =IF(AD22+AC23>=0,AD22+AC23,0) -> 628700.8 | AE23: =Y23+X23+G23+O23+AC23 -> 19783.722 | AF23: =-Grenzsteuersatz -> -0.42 | AH23: =AE23*AF23 -> -8309.1632 | AI23: =Y23+X23+F23+H23+N23+P23 -> -3865.2504 | AJ23: =AI23+AH23 -> -12174.414 | AK23: =+AJ23+AK22 -> -226001.23 | AM23: =AM22*(1+AM$6)+(AJ23/2)*AM$6+AJ23 -> -327508 | AN23: =+U23+AK23 -> 384245 | AO23: =+AM23+U23 -> 282738.22 | AQ23: =AQ22*(1+Wertzuwachst_des_Grundstücks_p.a.) -> 234515.73 | AR23: =AR22*(1-Wertverlust_des_Gebäudes_p.a.+Baukostensteigerung_p.a) -> 909779.77 | AS23: =AR23+AQ23 -> 1144295.5 | AT23: =(AS23-V23)*(V23>0) -> 655606.55 | AU23: =AS23+AN23-Investment -> 380340.5 | AW23: =AU23/Investment -> 0.33124934 | AX23: =(1+AW23)^(1/A23)-1 -> 0.018043213 | AY23: =IF(Eigenkapital>0,AU23/Eigenkapital,"n/a") -> 3.803405 | AZ23: =IF(Eigenkapital>0,(1+AY23)^(1/A23)-1,"n/a") -> 0.10305413 | BA23: =B23 -> 2041
